<?xml version="1.0"?>
<robot name="davinci" xmlns:xacro="http://www.ros.org/wiki/xacro">
  <link name="needle_driver_house">
    <visual>
      <origin
        xyz="0.0525 0 0"
        rpy="0 3.14159 -1.5708" />
      <geometry>
        <mesh
          filename="package://davinci_description/meshes/instruments/needle_driver_house.stl" />
      </geometry>
      <material
        name="blue">
      </material>
    </visual>
    <collision>
      <origin
        xyz="0.0525 0 0"
        rpy="0 3.14159 -1.5708" />
      <geometry>
        <mesh
          filename="package://davinci_description/meshes/instruments/needle_driver_house.stl" />
      </geometry>
    </collision>
  </link>

  <joint name="p4_instrument_roll"
    type="revolute">
    <origin
      xyz="0 0 0"
      rpy="0 0 0" />
    <parent
      link="needle_driver_house" />
    <child
      link="needle_driver_neck" />
    <axis
      xyz="0 0 1" />
    <limit
      lower="-4.712"
      upper="4.712"
      effort="1"
      velocity="1" />
  </joint>

  <link name="needle_driver_neck">
    <visual>
      <origin
        xyz="0 0 0"
        rpy="0 0 0" />
      <geometry>
        <mesh
          filename="package://davinci_description/meshes/instruments/needle_driver_neck.stl" />
      </geometry>
      <material
        name="slate">
      </material>
    </visual>
    <collision>
      <origin
        xyz="0 0 0"
        rpy="0 0 0" />
      <geometry>
        <mesh
          filename="package://davinci_description/meshes/instruments/needle_driver_neck.stl" />
      </geometry>
    </collision>
  </link>

  <joint name="p4_instrument_pitch"
    type="revolute">
    <origin
      xyz="0 0 0"
      rpy="0 1.5708 0" />
    <parent
      link="needle_driver_neck" />
    <child
      link="needle_driver_head" />
    <axis
      xyz="0 0 1" />
    <limit
      lower="-1.5"
      upper="1.5"
      effort="1"
      velocity="1" />
  </joint>

  <link name="needle_driver_head">
    <visual>
      <origin
        xyz="0 0 0"
        rpy="0 0 0" />
      <geometry>
        <mesh
          filename="package://davinci_description/meshes/instruments/needle_driver_head.stl" />
      </geometry>
      <material
        name="gray">
      </material>
    </visual>
    <collision>
      <origin
        xyz="0 0 0"
        rpy="0 0 0" />
      <geometry>
        <mesh
          filename="package://davinci_description/meshes/instruments/needle_driver_head.stl" />
      </geometry>
    </collision>
  </link>

  <joint name="p4_instrument_jaw_right"
    type="revolute">
    <origin
      xyz="0.009 0 0"
      rpy="-1.5708 0 0" />
    <parent
      link="needle_driver_head" />
    <child
      link="needle_driver_jawbone_right" />
    <axis
      xyz="0 0 1" />
    <limit
      lower="-1.8"
      upper="1.8"
      effort="1"
      velocity="1" />
  </joint>

  <link name="needle_driver_jawbone_right">
    <visual>
      <origin
        xyz="0 0 0"
        rpy="0 0 0" />
      <geometry>
        <mesh
          filename="package://davinci_description/meshes/instruments/needle_driver_jawbone_left.stl" />
      </geometry>
      <material
        name="gray">
      </material>
    </visual>
    <collision>
      <origin
        xyz="0 0 0"
        rpy="0 0 0" />
      <geometry>
        <mesh
          filename="package://davinci_description/meshes/instruments/needle_driver_jawbone_left.stl" />
      </geometry>
    </collision>
  </link>

  <link name="needle_driver_jawbone_left">
    <visual>
      <origin
        xyz="0 0 0"
        rpy="3.14159 0 0" />
      <geometry>
        <mesh
          filename="package://davinci_description/meshes/instruments/needle_driver_jawbone_left.stl" />
      </geometry>
      <material
        name="gray">
      </material>
    </visual>
    <collision>
      <origin
        xyz="0 0 0"
        rpy="3.14159 0 0" />
      <geometry>
        <mesh
          filename="package://davinci_description/meshes/instruments/needle_driver_jawbone_left.stl" />
      </geometry>
    </collision>
  </link>

  <joint name="p4_instrument_jaw_left"
    type="revolute">
    <origin
      xyz="0.009 0 0"
      rpy="-1.5708 0 0" />
    <parent
      link="needle_driver_head" />
    <child
      link="needle_driver_jawbone_left" />
    <axis
      xyz="0 0 1" />
    <limit
      lower="-1.8"
      upper="1.8"
      effort="1"
      velocity="1" />
  </joint>
</robot>