<?xml version="1.0"?>
<robot name="davinci" xmlns:xacro="http://www.ros.org/wiki/xacro">
  <link name="needle_driver_house">
    <inertial>
      <origin
        xyz="0.0487926923825119 1.2425463059237E-09 0.303878514609369"
        rpy="0 0 0" />
      <mass
        value="0.160905448095996" />
      <inertia
        ixx="0.000147992717312588"
        ixy="-4.85204886997006E-13"
        ixz="-2.43650182134419E-06"
        iyy="0.000117219380395437"
        iyz="-1.68887809351124E-11"
        izz="5.63867712385493E-05" />
    </inertial>
    <visual>
      <origin
        xyz="0.0525 0 0"
        rpy="0 3.14159 -1.5708" />
      <geometry>
        <mesh
          filename="package://davinci_description/meshes/instruments/needle_driver_house.stl" />
      </geometry>
      <material
        name="blue">
      </material>
    </visual>
    <collision>
      <origin
        xyz="0.0525 0 0"
        rpy="0 3.14159 -1.5708" />
      <geometry>
        <mesh
          filename="package://davinci_description/meshes/instruments/needle_driver_house.stl" />
      </geometry>
    </collision>
  </link>

  <link name="needle_driver_neck">
    <inertial>
      <origin
        xyz="1.88981532714125E-09 3.16376702613752E-10 -0.0401302981872702"
        rpy="0 0 0" />
      <mass
        value="0.0232510537357557" />
      <inertia
        ixx="0.000357953997322209"
        ixy="-1.09841765686305E-13"
        ixz="7.75110601988088E-12"
        iyy="0.000357954438471494"
        iyz="1.3024211024653E-12"
        izz="2.00399317932057E-07" />
    </inertial>
    <visual>
      <origin
        xyz="0 0 0"
        rpy="0 0 0" />
      <geometry>
        <mesh
          filename="package://davinci_description/meshes/instruments/needle_driver_neck.stl" />
      </geometry>
      <material
        name="slate">
      </material>
    </visual>
    <collision>
      <origin
        xyz="0 0 0"
        rpy="0 0 0" />
      <geometry>
        <mesh
          filename="package://davinci_description/meshes/instruments/needle_driver_neck.stl" />
      </geometry>
    </collision>
  </link>

  <joint name="p4_instrument_roll"
    type="revolute">
    <origin
      xyz="0.0525000000003168 0 0"
      rpy="3.14159265358979 -1.45892264612837E-16 1.5707963267949" />
    <parent
      link="needle_driver_house" />
    <child
      link="needle_driver_neck" />
    <axis
      xyz="0 0 1" />
    <limit
      lower="-4.712"
      upper="4.712"
      effort="1"
      velocity="1" />
    <dynamics damping="0"/>
  </joint>

  <link name="needle_driver_head">
    <inertial>
      <origin
        xyz="2.82477802579071E-06 -3.6037163499536E-05 0.00301833175193345"
        rpy="0 0 0" />
      <mass
        value="0.000234269246654977" />
      <inertia
        ixx="2.57553175127649E-09"
        ixy="-1.7088879166498E-11"
        ixz="4.50036079768168E-13"
        iyy="2.37501406336667E-09"
        iyz="-1.57952093810846E-11"
        izz="1.24185526283754E-09" />
    </inertial>
    <visual>
      <origin
        xyz="0 0 0"
        rpy="0 0 0" />
      <geometry>
        <mesh
          filename="package://davinci_description/meshes/instruments/needle_driver_head.stl" />
      </geometry>
      <material
        name="gray">
      </material>
    </visual>
    <collision>
      <origin
        xyz="0 0 0"
        rpy="0 0 0" />
      <geometry>
        <mesh
          filename="package://davinci_description/meshes/instruments/needle_driver_head.stl" />
      </geometry>
    </collision>
  </link>

  <joint name="p4_instrument_pitch"
    type="revolute">
    <origin
      xyz="0 0 0.177"
      rpy="0 0 0" />
    <parent
      link="needle_driver_neck" />
    <child
      link="needle_driver_head" />
    <axis
      xyz="1 0 0" />
    <limit
      lower="-1.5"
      upper="1.5"
      effort="1"
      velocity="1" />
    <dynamics damping="0"/>
  </joint>

  <link name="needle_driver_jawbone_left">
    <inertial>
      <origin
        xyz="-0.00211142946935594 0.000167266219560752 -0.000657389690164489"
        rpy="0 0 0" />
      <mass
        value="4.72823027124423E-05" />
      <inertia
        ixx="7.07960996815586E-11"
        ixy="-3.38178696144901E-11"
        ixz="-5.27585618542085E-11"
        iyy="4.60880145483977E-10"
        iyz="5.64458037529414E-12"
        izz="4.87285720312733E-10" />
    </inertial>
    <visual>
      <origin
        xyz="0 0 0"
        rpy="0 0 0" />
      <geometry>
        <mesh
          filename="package://davinci_description/meshes/instruments/needle_driver_jawbone_left.stl" />
      </geometry>
      <material
        name="gray">
      </material>
    </visual>
    <collision>
      <origin
        xyz="0 0 0"
        rpy="0 0 0" />
      <geometry>
        <mesh
          filename="package://davinci_description/meshes/instruments/needle_driver_jawbone_left.stl" />
      </geometry>
    </collision>
  </link>

  <joint name="p4_instrument_jaw_left"
    type="revolute">
    <origin
      xyz="0 0 0.00900000000000001"
      rpy="1.5707963267949 1.5707963267949 0" />
    <parent
      link="needle_driver_head" />
    <child
      link="needle_driver_jawbone_left" />
    <axis
      xyz="0 0 1" />
    <limit
      lower="-1.8"
      upper="1.8"
      effort="1"
      velocity="1" />
    <dynamics damping="0"/>
  </joint>

  <link name="needle_driver_jawbone_right">
    <inertial>
      <origin
        xyz="-0.00211142946935583 0.000167266219581923 -0.000749389690795965"
        rpy="0 0 0" />
      <mass
        value="4.72823027124613E-05" />
      <inertia
        ixx="7.07960996815865E-11"
        ixy="-3.38178696144904E-11"
        ixz="-5.27585618541835E-11"
        iyy="4.60880145483901E-10"
        iyz="5.64458037527874E-12"
        izz="4.87285720312658E-10" />
    </inertial>
    <visual>
      <origin
        xyz="0 0 0"
        rpy="3.14159 0 0" />
      <geometry>
        <mesh
          filename="package://davinci_description/meshes/instruments/needle_driver_jawbone_right.stl" />
      </geometry>
      <material
        name="gray">
      </material>
    </visual>
    <collision>
      <origin
        xyz="0 0 0"
        rpy="3.14159 0 0" />
      <geometry>
        <mesh
          filename="package://davinci_description/meshes/instruments/needle_driver_jawbone_right.stl" />
      </geometry>
    </collision>
  </link>

  <joint name="p4_instrument_jaw_right"
    type="revolute">
    <origin
      xyz="0 0 0.00900000000000001"
      rpy="1.5707963267949 1.5707963267949 0" />
    <parent
      link="needle_driver_head" />
    <child
      link="needle_driver_jawbone_right" />
    <axis
      xyz="0 0 -1" />
    <limit
      lower="-1.8"
      upper="1.8"
      effort="1"
      velocity="1" />
    <dynamics damping="0" friction="0.1"/>
  </joint>
</robot>