<?xml version="1.0" ?>
<!-- =================================================================================== -->
<!-- |    EDITING THIS FILE BY HAND IS NOT RECOMMENDED                                 | -->
<!-- =================================================================================== -->
<!-- Revolute-Revolute Manipulator -->
<robot name="davinci" xmlns:xacro="http://www.ros.org/wiki/xacro">
  <!-- Constants for robot dimensions -->
  <!-- Square dimensions (widthxwidth) of beams -->
  <!-- Link 1 -->
  <!-- Link 2 -->
  <!-- Link 3 -->
  <!-- Size of square 'camera' box -->
  <!-- Space btw top of beam and the each joint -->
  <!-- Import all Gazebo-customization elements, including Gazebo colors -->
  <gazebo>
    <plugin filename="libgazebo_ros_control.so" name="ros_control">
      <robotNamespace>/davinci</robotNamespace>
    </plugin>
  </gazebo>
  <!-- base_link -->
  <gazebo reference="base_link">
    <material>Gazebo/Orange</material>
  </gazebo>

  <!-- p4_arm_base -->
  <gazebo reference="p4_arm_base">
    <mu1>0.2</mu1>
    <mu2>0.2</mu2>
    <material>Gazebo/Black</material>
  </gazebo>

  <!-- p4_arm1 -->
  <gazebo reference="p4_arm1">
    <mu1>0.2</mu1>
    <mu2>0.2</mu2>
    <material>Gazebo/Orange</material>
  </gazebo>

  <!-- p4_arm2 -->
  <gazebo reference="p4_arm2">
    <mu1>0.2</mu1>
    <mu2>0.2</mu2>
    <material>Gazebo/Orange</material>
  </gazebo>

  <!-- p4_arm3 -->
  <gazebo reference="p4_arm3">
    <mu1>0.2</mu1>
    <mu2>0.2</mu2>
    <material>Gazebo/Orange</material>
  </gazebo>

  <!-- p4_arm4 -->
  <gazebo reference="p4_arm4">
    <mu1>0.2</mu1>
    <mu2>0.2</mu2>
    <material>Gazebo/Orange</material>
  </gazebo>

  <!-- p4_hand1 -->
  <gazebo reference="p4_hand1">
    <mu1>0.2</mu1>
    <mu2>0.2</mu2>
    <material>Gazebo/Orange</material>
  </gazebo>

  <!-- p4_hand2 -->
  <gazebo reference="p4_hand2">
    <mu1>0.2</mu1>
    <mu2>0.2</mu2>
    <material>Gazebo/Orange</material>
  </gazebo>

  <!-- p4_hand3 -->
  <gazebo reference="p4_hand3">
    <mu1>0.2</mu1>
    <mu2>0.2</mu2>
    <material>Gazebo/Orange</material>
  </gazebo>

  <!-- p4_hand4 -->
  <gazebo reference="p4_hand4">
    <mu1>0.2</mu1>
    <mu2>0.2</mu2>
    <material>Gazebo/Orange</material>
  </gazebo>

  <!-- p4_hand5 -->
  <gazebo reference="p4_hand5">
    <mu1>0.2</mu1>
    <mu2>0.2</mu2>
    <material>Gazebo/Orange</material>
  </gazebo>

  <!-- p4_instrument_house -->
  <gazebo reference="p4_instrument_house">
    <mu1>0.2</mu1>
    <mu2>0.2</mu2>
    <material>Gazebo/Orange</material>
  </gazebo>
  
  
  <!-- Import Rviz colors -->
  <material name="black">
    <color rgba="0.0 0.0 0.0 1.0"/>
  </material>
  <material name="blue">
    <color rgba="0.0 0.0 0.8 1.0"/>
  </material>
  <material name="green">
    <color rgba="0.0 0.8 0.0 1.0"/>
  </material>
  <material name="grey">
    <color rgba="0.2 0.2 0.2 1.0"/>
  </material>
  <material name="orange">
    <color rgba="1.0 0.423529411765 0.0392156862745 1.0"/>
  </material>
  <material name="brown">
    <color rgba="0.870588235294 0.811764705882 0.764705882353 1.0"/>
  </material>
  <material name="red">
    <color rgba="0.8 0.0 0.0 1.0"/>
  </material>
  <material name="white">
    <color rgba="1.0 1.0 1.0 1.0"/>
  </material>
  <!-- Used for fixing robot to Gazebo 'base_link' -->
  <link name="world"/>
  <joint name="fixed" type="fixed">
    <parent link="world"/>
    <child link="base_link"/>
  </joint>

  <!-- Base Link -->
  <link name="base_link">
    <inertial>
      <origin
        xyz="-0.0675046389711765 8.91088155245749E-05 0.605417822180421"
        rpy="0 0 0" />
      <mass value="146.854044008417" />
      <inertia
        ixx="53.2772368865768"
        ixy="-0.000537499922686351"
        ixz="-0.353365610342839"
        iyy="51.7014979851064"
        iyz="0.005825469343997"
        izz="12.1256510580484" />
    </inertial>
    <visual>
      <origin
        xyz="0 0 0"
        rpy="0 0 0" />
      <geometry>
        <mesh filename="package://davinci_description/meshes/base_link.STL" />
      </geometry>
      <material name="orange"/>
    </visual>
    <collision>
      <origin
        xyz="0 0 1"
        rpy="0 0 0" />
      <geometry>
	<box size="0.2 0.2 2"/>
      </geometry>
    </collision>
  </link>

  <joint name="p4_arm_elevation" type="fixed">
    <parent link="base_link"/>
    <child link="p4_arm_base"/>
    <origin
      xyz="0 0 0"
      rpy="0 0 0" />
    <axis xyz="0 0 1"/>
    <limit
      lower="0"
      upper="1"
      effort="10000"
      velocity="1" />
  </joint>

  <!-- p4_arm_base -->
  <link name="p4_arm_base">
    <inertial>
      <origin
        xyz="0.160243136797189 2.85409670446341E-08 0.456149873456073"
        rpy="0 0 0" />
      <mass value="4.57690792902629" />
      <inertia
        ixx="0.0278474387988703"
        ixy="2.17385160271678E-09"
        ixz="0.00478577326846734"
        iyy="0.030426196193991"
        iyz="5.47753575213966E-09"
        izz="0.0164535598169594" />
    </inertial>
    <visual>
      <origin
        xyz="0.186 0 0.554"
        rpy="0 3.1416 -1.5708" />
      <geometry>
        <mesh filename="package://davinci_description/meshes/p4-arm-base.STL" />
      </geometry>
      <material name="black"/>
    </visual>
    <collision>
      <origin
        xyz="0.186 0 0.5"
        rpy="0 3.1416 -1.5708" />
      <geometry>
	<box size="0.15 0.15 0.15"/>
      </geometry>
    </collision>
  </link>

  <joint name="p4_arm_yaw1" type="fixed">
    <parent link="p4_arm_base"/>
    <child link="p4_arm1"/>
    <origin
      xyz="0.186 0 0.5544"
      rpy="3.1416 0 1.5708" />
    <axis xyz="0 0 1"/>
  <limit
      lower="-1.5708"
      upper="1.5708"
      effort="1"
      velocity="1" />
    <dynamics damping="0.7"/>
  </joint>

  <!-- p4_arm1 -->
  <link name="p4_arm1">
    <inertial>
      <origin
        xyz="4.61971513685182E-07 0.252962848969993 -0.0998729966694851"
        rpy="0 0 0" />
      <mass
        value="12.0042352614557" />
      <inertia
        ixx="0.655055659176488"
        ixy="5.48844410493802E-07"
        ixz="-1.28029383672488E-07"
        iyy="0.0516630488844251"
        iyz="0.0509757118566697"
        izz="0.630178454580182" />
    </inertial>
    <visual>
      <origin
        xyz="0 0 0"
        rpy="0 0 0" />
      <geometry>
        <mesh
          filename="package://davinci_description/meshes/p4-arm1.STL" />
      </geometry>
      <material name="orange"/>
    </visual>
    <collision>
      <origin
        xyz="0 0.3 -0.09"
        rpy="1.5708 0 0" />
      <geometry>
	<cylinder length="0.6" radius="0.06"/>
      </geometry>
    </collision>
  </link>
  <joint name="p4_arm_yaw2"
    type="fixed">
    <origin
      xyz="0 0.58285 0"
      rpy="-3.14159265358979 1.24808068980918E-16 1.5707963267949" />
    <parent
      link="p4_arm1" />
    <child
      link="p4_arm2" />
    <axis
      xyz="0 0 -1" />
    <limit
      lower="-2.8"
      upper="2.8"
      effort="1"
      velocity="1" />
  <dynamics damping="0.7"/>
  </joint>
  <link name="p4_arm2">
    <inertial>
      <origin
        xyz="0.224760417587176 8.48400769093145E-07 -0.0850912705183845"
        rpy="0 0 0" />
      <mass
        value="7.45119488647257" />
      <inertia
        ixx="0.0275878615794263"
        ixy="4.5800742788229E-07"
        ixz="0.00335338124805321"
        iyy="0.308891515610292"
        iyz="5.64514197495912E-08"
        izz="0.292533880572453" />
    </inertial>
    <visual>
      <origin
        xyz="0 0 0"
        rpy="0 0 0" />
      <geometry>
        <mesh
          filename="package://davinci_description/meshes/p4-arm2.STL" />
      </geometry>
      <material
        name="orange">
      </material>
    </visual>
    <collision>
      <origin
        xyz="0.25 0 -0.06"
        rpy="0 1.5708 0" />
      <geometry>
	<cylinder length="0.5" radius="0.05"/>
      </geometry>
    </collision>
  </link>
  <joint name="p4_arm_yaw3"
    type="fixed">
    <origin
      xyz="0.47985 0 -0.001"
      rpy="-4.41862941934989E-22 2.30317389564735E-22 -1.30104260698261E-18" />
    <parent
      link="p4_arm2" />
    <child
      link="p4_arm3" />
    <axis
      xyz="0 0 -1" />
    <limit
      lower="-2.8"
      upper="2.8"
      effort="1"
      velocity="1" />
<dynamics damping="0"/>
  </joint>
  <link name="p4_arm3">
    <inertial>
      <origin
        xyz="-0.0267512630921443 -1.93250659384755E-09 0.145900313046248"
        rpy="0 0 0" />
      <mass
        value="2.6382273355906" />
      <inertia
        ixx="0.0142167625502172"
        ixy="-7.64335373930088E-10"
        ixz="-0.00369461362533997"
        iyy="0.0202734840263692"
        iyz="8.69325247473299E-10"
        izz="0.00910404517257023" />
    </inertial>
    <visual>
      <origin
        xyz="0 0 0"
        rpy="0 0 0" />
      <geometry>
        <mesh
          filename="package://davinci_description/meshes/p4-arm3.STL" />
      </geometry>
      <material
        name="surgical gray">
        <color rgba="0.67 0.65 0.64 1.0" />
      </material>
    </visual>
    <collision>
      <origin
        xyz="0 0 0.1"
        rpy="0 0 0" />
      <geometry>
        <!--<mesh
          filename="package://davinci_description/meshes/p4-arm3.STL" />-->
        <cylinder length="0.2" radius="0.05"/>
      </geometry>
    </collision>
  </link>
  <joint name="p4_arm_roll1"
    type="fixed">
    <origin
      xyz="0.0569999999999999 0 0.19825"
      rpy="-2.72945570336682E-16 2.973835489358E-19 -9.62964972193618E-35" />
    <parent
      link="p4_arm3" />
    <child
      link="p4_arm4" />
    <axis
      xyz="-1 0 0" />
    <limit
      lower="-1.5708"
      upper="1.5708"
      effort="1"
      velocity="1" />
<dynamics damping="0"/>
  </joint>
  <link name="p4_arm4">
    <inertial>
      <origin
        xyz="0.173920536091799 -3.18908971983827E-08 -0.123558701456668"
        rpy="0 0 0" />
      <mass
        value="1.95333539219675" />
      <inertia
        ixx="0.00770368154372411"
        ixy="-5.57845552280854E-09"
        ixz="-0.010159511354247"
        iyy="0.0455698238811277"
        iyz="1.87011128879721E-09"
        izz="0.039386691329167" />
    </inertial>
    <visual>
      <origin
        xyz="0 0 0"
        rpy="0 0 0" />
      <geometry>
        <mesh
          filename="package://davinci_description/meshes/p4-arm4.STL" />
      </geometry>
      <material
        name="surgical gray">
      </material>
    </visual>
    <collision>
      <origin
        xyz="0.18 0 -0.15"
        rpy="0 1.5708 0" />
      <geometry>
        <!--<mesh
          filename="package://davinci_description/meshes/p4-arm4.STL" />-->
        <cylinder length="0.35" radius="0.026"/>
      </geometry>
    </collision>
  </link>
  <joint name="p4_arm_yaw4"
    type="fixed">
    <origin
      xyz="0.35225 0 -0.117"
      rpy="3.22833053553567E-17 2.04577519985781E-18 8.67361737988404E-19" />
    <parent
      link="p4_arm4" />
    <child
      link="p4_hand1" />
    <axis
      xyz="0 0 1" />
    <limit
      lower="-2.8"
      upper="2.8"
      effort="1"
      velocity="1" />
<dynamics damping="0"/>
  </joint>
  <link name="p4_hand1">
    <inertial>
      <origin
        xyz="-0.141020957350944 1.21214233081955E-17 0.0663841857186647"
        rpy="0 0 0" />
      <mass
        value="0.621071194298928" />
      <inertia
        ixx="0.00177515722579009"
        ixy="-3.42947384120289E-19"
        ixz="-0.00132485758671836"
        iyy="0.0106058839388964"
        iyz="-1.91469582712511E-20"
        izz="0.00946910994713563" />
    </inertial>
    <visual>
      <origin
        xyz="0 0 0"
        rpy="0 0 0" />
      <geometry>
        <mesh
          filename="package://davinci_description/meshes/p4-hand1.STL" />
      </geometry>
      <material name="slate">
        <color rgba="0.2 0.2 0.2 1"/>
     </material>
    </visual>
    <collision>
      <origin
        xyz="0 0 0"
        rpy="0 0 0" />
      <geometry>
        <mesh
          filename="package://davinci_description/meshes/p4-hand1.STL" />
      </geometry>
    </collision>
  </link>
  <joint name="p4_hand_roll"
    type="revolute">
    <origin
      xyz="-0.0424999999999998 0 0.160999999999999"
      rpy="0 1.22464679914735E-16 0" />
    <parent
      link="p4_hand1" />
    <child
      link="p4_hand2" />
    <axis
      xyz="1 0 0" />
    <limit
      lower="-1.5708"
      upper="1.5708"
      effort="1"
      velocity="1" />
<dynamics damping="0"/>
  </joint>
  <link name="p4_hand2">
    <inertial>
      <origin
        xyz="-0.034905365724315 0.0169015146796576 -0.00639701999425513"
        rpy="0 0 0" />
      <mass
        value="0.282965703322585" />
      <inertia
        ixx="0.000932689448159107"
        ixy="0.000166936621539662"
        ixz="6.91827841364329E-05"
        iyy="0.00267151701316434"
        iyz="-3.03623107893296E-05"
        izz="0.00350055099215538" />
    </inertial>
    <visual>
      <origin
        xyz="0 0 0"
        rpy="0 0 0" />
      <geometry>
        <mesh
          filename="package://davinci_description/meshes/p4-hand2.STL" />
      </geometry>
      <material
        name="slate"
      />
    </visual>
    <collision>
      <origin
        xyz="0 0 0"
        rpy="0 0 0" />
      <geometry>
        <mesh
          filename="package://davinci_description/meshes/p4-hand2.STL" />
      </geometry>
    </collision>
  </link>
  <joint name="p4_hand_pitch"
    type="revolute">
    <origin
      xyz="0 0 0"
      rpy="3.42136669122662E-16 -0.288812097817057 -1.17706479711569E-17" />
    <parent
      link="p4_hand2" />
    <child
      link="p4_hand3" />
    <axis
      xyz="0 1 0" />
    <limit
      lower="-0.8"
      upper="1.0"
      effort="1"
      velocity="1" />
<dynamics damping="0"/>
  </joint>
  <link name="p4_hand3">
    <inertial>
      <origin
        xyz="-0.00847368219377387 1.24148413866933E-18 -0.0484521850605982"
        rpy="0 0 0" />
      <mass
        value="1.10069000101175" />
      <inertia
        ixx="0.00525153454291773"
        ixy="-1.36844956033732E-20"
        ixz="3.76083212771966E-05"
        iyy="0.0055009793007968"
        iyz="1.4922931008841E-18"
        izz="0.00222337171572136" />
    </inertial>
    <visual>
      <origin
        xyz="0 0 0"
        rpy="0 0 0" />
      <geometry>
        <mesh
          filename="package://davinci_description/meshes/p4-hand3.STL" />
      </geometry>
      <material
        name="slate"
      />
    </visual>
    <collision>
      <origin
        xyz="0 0 0"
        rpy="0 0 0" />
      <geometry>
        <mesh
          filename="package://davinci_description/meshes/p4-hand3.STL" />
      </geometry>
    </collision>
  </link>
<joint name="p4_hand_pitch2"
    type="continuous">
    <origin
      xyz="0.0108229214977171 0 0.186426149539229"
      rpy="3.14159265358979 0.288812097814836 9.64324654702006E-17" />
    <parent
      link="p4_hand3" />
    <child
      link="p4_hand4" />
    <axis
      xyz="0 1 0" />
<mimic joint="p4_hand_pitch" multiplier="1.0" offset="0.0" />
<dynamics damping="0"/>
  </joint>
  <link name="p4_hand4">
    <inertial>
      <origin
        xyz="0.263815032211533 4.68378885044887E-17 5.85864690094695E-13"
        rpy="0 0 0" />
      <mass
        value="0.447187973747169" />
      <inertia
        ixx="0.000213553859784005"
        ixy="1.40608230969305E-18"
        ixz="2.10898038420179E-14"
        iyy="0.00951490256513373"
        iyz="-2.13582514230218E-20"
        izz="0.00970925259610884" />
    </inertial>
    <visual>
      <origin
        xyz="0 0 0"
        rpy="0 0 0" />
      <geometry>
        <mesh
          filename="package://davinci_description/meshes/p4-hand4.STL" />
      </geometry>
      <material
        name="slate"
      />
    </visual>
    <collision>
      <origin
        xyz="0 0 0"
        rpy="0 0 0" />
      <geometry>
        <mesh
          filename="package://davinci_description/meshes/p4-hand4.STL" />
      </geometry>
    </collision>
  </link>
<joint name="p4_hand_pitch3"
    type="continuous">
    <origin
      xyz="0.52 0 0"
      rpy="3.14159265358979 -2.22109682611874E-12 6.08324503520137E-16" />
    <parent
      link="p4_hand4" />
    <child
      link="p4_hand5" />
    <axis
      xyz="0 -1 0" />
<mimic joint="p4_hand_pitch" multiplier="-1.0" offset="0.0" />
<dynamics damping="0"/>
  </joint>
  <link name="p4_hand5">
    <inertial>
      <origin
        xyz="0.010300033112455 -5.64698404664002E-08 0.115001494794893"
        rpy="0 0 0" />
      <mass
        value="1.36700413065379" />
      <inertia
        ixx="0.0256569523936302"
        ixy="3.66772348419097E-10"
        ixz="-0.000709993776572381"
        iyy="0.0251602021413385"
        iyz="9.1909743907129E-09"
        izz="0.000966623316671537" />
    </inertial>
    <visual>
      <origin
        xyz="0 0 0"
        rpy="0 0 0" />
      <geometry>
        <mesh
          filename="package://davinci_description/meshes/p4-hand5.STL" />
      </geometry>
      <material
        name="slate"
      />
    </visual>
    <collision>
      <origin
        xyz="0 0 0.15"
        rpy="0 0 0" />
      <geometry>
        <!--<mesh
          filename="package://davinci_description/meshes/p4-hand5.STL" />-->
        <box size="0.03 0.08 0.4"/>
      </geometry>
    </collision>
  </link>
  <joint name="p4_instrument_slide"
    type="prismatic">
    <origin
      xyz="0 0 0"
      rpy="0 0 0" />
    <parent
      link="p4_hand5" />
    <child
      link="p4_instrument_house" />
    <axis
      xyz="0 0 -1" />
    <limit
      lower="0"
      upper="0.3"
      effort="1"
      velocity="1" />
<dynamics damping="0"/>
  </joint>
  <link name="p4_instrument_house">
    <inertial>
      <origin
        xyz="0.0487926923825119 1.2425463059237E-09 0.303878514609369"
        rpy="0 0 0" />
      <mass
        value="0.160905448095996" />
      <inertia
        ixx="0.000147992717312588"
        ixy="-4.85204886997006E-13"
        ixz="-2.43650182134419E-06"
        iyy="0.000117219380395437"
        iyz="-1.68887809351124E-11"
        izz="5.63867712385493E-05" />
    </inertial>
    <visual>
      <origin
        xyz="0.0525 0 0"
        rpy="0 3.14159 -1.5708" />
      <geometry>
        <mesh
          filename="package://davinci_description/meshes/p4-instrument-house.STL" />
      </geometry>
      <material
        name="blue">
        <color
          rgba="0.3 0.3 1 1"/>
      </material>
    </visual>
    <collision>
      <origin
        xyz="0.0487926923825119 0 0.3"
        rpy="0 0 0" />
      <geometry>
        <!--<mesh
          filename="package://davinci_description/meshes/p4-instrument-house.STL" />-->
        <box size="0.025 0.05 0.1"/>
      </geometry>
    </collision>
  </link>
  <joint name="p4_instrument_roll"
    type="continuous">
    <origin
      xyz="0.0525000000003168 0 0"
      rpy="3.14159265358979 -1.45892264612837E-16 1.5707963267949" />
    <parent
      link="p4_instrument_house" />
    <child
      link="p4_instrument_neck" />
    <axis
      xyz="0 0 1" />
<dynamics damping="0"/>
  </joint>
  <link name="p4_instrument_neck">
    <inertial>
      <origin
        xyz="1.88981532714125E-09 3.16376702613752E-10 -0.0401302981872702"
        rpy="0 0 0" />
      <mass
        value="0.0232510537357557" />
      <inertia
        ixx="0.000357953997322209"
        ixy="-1.09841765686305E-13"
        ixz="7.75110601988088E-12"
        iyy="0.000357954438471494"
        iyz="1.3024211024653E-12"
        izz="2.00399317932057E-07" />
    </inertial>
    <visual>
      <origin
        xyz="0 0 0"
        rpy="0 0 0" />
      <geometry>
        <mesh
          filename="package://davinci_description/meshes/p4-instrument-neck.STL" />
      </geometry>
      <material
        name="slate">
      </material>
    </visual>
    <collision>
      <origin
        xyz="0 0 -0.048"
        rpy="0 0 0" />
      <geometry>
        <!--<mesh     
filename="package://davinci_description/meshes/p4-instrument-neck.STL" />
-->
        <cylinder length="0.45" radius="0.004"/>
      </geometry>
    </collision>
  </link>
 

<joint name="p4_instrument_pitch"
    type="continuous">
    <origin
      xyz="0 0 0.177"
      rpy="0 0 0" />
    <parent
      link="p4_instrument_neck" />
    <child
      link="p4_instrument_head" />
    <axis
      xyz="1 0 0" />
<dynamics damping="0"/>
  </joint>
<link name="p4_instrument_head">
    <inertial>
      <origin
        xyz="2.82477802579071E-06 -3.6037163499536E-05 0.00301833175193345"
        rpy="0 0 0" />
      <mass
        value="0.000234269246654977" />
      <inertia
        ixx="2.57553175127649E-09"
        ixy="-1.7088879166498E-11"
        ixz="4.50036079768168E-13"
        iyy="2.37501406336667E-09"
        iyz="-1.57952093810846E-11"
        izz="1.24185526283754E-09" />
    </inertial>
    <visual>
      <origin
        xyz="0 0 0"
        rpy="0 0 0" />
      <geometry>
        <mesh
          filename="package://davinci_description/meshes/p4-instrument-head.STL" />
      </geometry>
      <material
        name="gray">
        <color
          rgba="0.5 0.5 0.5 1"/>
      </material>
    </visual>
    <collision>
      <origin
        xyz="0 0 0"
        rpy="0 0 0" />
      <geometry>
        <mesh
          filename="package://davinci_description/meshes/p4-instrument-head.STL" />
      </geometry>
    </collision>
  </link>
  
  <joint name="p4_instrument_jaw_left"
    type="continuous">
    <origin
      xyz="0 0 0.00900000000000001"
      rpy="1.5707963267949 1.5707963267949 0" />
    <parent
      link="p4_instrument_head" />
    <child
      link="p4_instrument_jawbone_left" />
    <axis
      xyz="0 0 1" />
<dynamics damping="0"/>
  </joint>
  <link name="p4_instrument_jawbone_left">
    <inertial>
      <origin
        xyz="-0.00211142946935594 0.000167266219560752 -0.000657389690164489"
        rpy="0 0 0" />
      <mass
        value="4.72823027124423E-05" />
      <inertia
        ixx="7.07960996815586E-11"
        ixy="-3.38178696144901E-11"
        ixz="-5.27585618542085E-11"
        iyy="4.60880145483977E-10"
        iyz="5.64458037529414E-12"
        izz="4.87285720312733E-10" />
    </inertial>
    <visual>
      <origin
        xyz="0 0 0"
        rpy="0 0 0" />
      <geometry>
        <mesh
          filename="package://davinci_description/meshes/p4-instrument-jawbone-left.STL" />
      </geometry>
      <material
        name="gray">
      </material>
    </visual>
    <collision>
      <origin
        xyz="0 0 0"
        rpy="0 0 0" />
      <geometry>
        <mesh
          filename="package://davinci_description/meshes/p4-instrument-jawbone-left.STL" />
      </geometry>
    </collision>
  </link>
  <joint name="p4_instrument_jaw_right"
    type="continuous">
    <origin
      xyz="0 0 0.00900000000000001"
      rpy="1.5707963267949 1.5707963267949 0" />
    <parent
      link="p4_instrument_head" />
    <child
      link="p4_instrument_jawbone_right" />
    <axis
      xyz="0 0 -1" />
<dynamics damping="0" friction="0.1"/>
  </joint>
  <link name="p4_instrument_jawbone_right">
    <inertial>
      <origin
        xyz="-0.00211142946935583 0.000167266219581923 -0.000749389690795965"
        rpy="0 0 0" />
      <mass
        value="4.72823027124613E-05" />
      <inertia
        ixx="7.07960996815865E-11"
        ixy="-3.38178696144904E-11"
        ixz="-5.27585618541835E-11"
        iyy="4.60880145483901E-10"
        iyz="5.64458037527874E-12"
        izz="4.87285720312658E-10" />
    </inertial>
    <visual>
      <origin
        xyz="0 0 0"
        rpy="3.14159 0 0" />
      <geometry>
        <mesh
          filename="package://davinci_description/meshes/p4-instrument-jawbone-right.STL" />
      </geometry>
      <material
        name="gray">
      </material>
    </visual>
    <collision>
      <origin
        xyz="0 0 0"
        rpy="3.14159 0 0" />
      <geometry>
        <mesh
          filename="package://davinci_description/meshes/p4-instrument-jawbone-right.STL" />
      </geometry>
    </collision>
  </link>

  <transmission name="tran1">
    <type>transmission_interface/SimpleTransmission</type>
    <joint name="p4_hand_roll"/>
    <actuator name="motor1">
      <hardwareInterface>EffortJointInterface</hardwareInterface>
      <mechanicalReduction>1</mechanicalReduction>
    </actuator>
  </transmission>
  <transmission name="tran2">
    <type>transmission_interface/SimpleTransmission</type>
    <joint name="p4_hand_pitch"/>
    <actuator name="motor2">
      <hardwareInterface>EffortJointInterface</hardwareInterface>
      <mechanicalReduction>1</mechanicalReduction>
    </actuator>
  </transmission> 
  <transmission name="tran3">
    <type>transmission_interface/SimpleTransmission</type>
    <joint name="p4_instrument_slide"/>
    <actuator name="motor3">
      <hardwareInterface>EffortJointInterface</hardwareInterface>
      <mechanicalReduction>1</mechanicalReduction>
    </actuator>
  </transmission>
  <transmission name="tran4">
    <type>transmission_interface/SimpleTransmission</type>
    <joint name="p4_instrument_roll"/>
    <actuator name="motor4">
      <hardwareInterface>EffortJointInterface</hardwareInterface>
      <mechanicalReduction>1</mechanicalReduction>
    </actuator>
  </transmission>
  <transmission name="tran5">
    <type>transmission_interface/SimpleTransmission</type>
    <joint name="p4_instrument_pitch"/>
    <actuator name="motor5">
      <hardwareInterface>EffortJointInterface</hardwareInterface>
      <mechanicalReduction>1</mechanicalReduction>
    </actuator>
  </transmission>
  <transmission name="tran6">
    <type>transmission_interface/SimpleTransmission</type>
    <joint name="p4_instrument_jaw_left"/>
    <actuator name="motor6">
      <hardwareInterface>EffortJointInterface</hardwareInterface>
      <mechanicalReduction>1</mechanicalReduction>
    </actuator>
  </transmission>
  <transmission name="tran7">
    <type>transmission_interface/SimpleTransmission</type>
    <joint name="p4_instrument_jaw_right"/>
    <actuator name="motor7">
      <hardwareInterface>EffortJointInterface</hardwareInterface>
      <mechanicalReduction>1</mechanicalReduction>
    </actuator>
  </transmission>

</robot>
