<?xml version="1.0"?>
<robot name="davinci" xmlns:xacro="http://www.ros.org/wiki/xacro">

  <xacro:include filename="$(find davinci_description)/robots/davinci_link_macro.xacro" />

  <xacro:davinci_link name="p4_rcm_base" color="slate" />

  <joint name="p4_hand_roll"
    type="revolute">
    <origin
      xyz="0.482 0 0.047"
      rpy="0 1.5708 0" />
    <parent
      link="p4_rcm_base" />
    <child
      link="rcm_vitual0" />
    <axis
      xyz="0 0 1" />
    <limit
      lower="-1.5708"
      upper="1.5708"
      effort="1"
      velocity="1" />
  </joint>

  <link name="rcm_vitual0" />

  <joint name="p4_hand_pitch"
    type="revolute">
    <origin
      xyz="0 0 0"
      rpy="1.5708 0 0" />
    <parent
      link="rcm_vitual0" />
    <child
      link="rcm_vitual1" />
    <axis
      xyz="0 0 1" />
    <limit
      lower="-0.8"
      upper="1.0"
      effort="1"
      velocity="1" />
  </joint>

  <link name="rcm_vitual1" />

  <joint name="p4_instrument_slide"
    type="prismatic">
    <origin
      xyz="0.097 0 0"
      rpy="0 -1.5708 0" />
    <parent
      link="rcm_vitual1" />
    <child
      link="needle_driver_house" />
    <axis
      xyz="0 0 1" />
    <limit
      lower="-0.12"
      upper="0.12"
      effort="1"
      velocity="1" />
  </joint>

</robot>
