<?xml version="1.0"?>
<robot name="davinci" xmlns:xacro="http://www.ros.org/wiki/xacro">

  <xacro:include filename="$(find davinci_description)/robots/davinci_link_macro.xacro" />

  <xacro:davinci_link name="base_link" color="surgical gray"/>

  <joint name="p4_arm_elevation" type="prismatic">
    <parent link="base_link"/>
    <child link="p4_arm_base"/>
    <origin
      xyz="0 0 0.998"
      rpy="0 0 0" />
    <axis xyz="0 0 1"/>
    <limit
      lower="0"
      upper="1"
      effort="10000"
      velocity="1" />
  </joint>

</robot>
