<?xml version="1.0"?>
<robot name="davinci" xmlns:xacro="http://www.ros.org/wiki/xacro">

  <xacro:include filename="$(find davinci_description)/robots/davinci_link_macro.xacro" />

  <xacro:davinci_link name="base_link"
    color="surgical gray">
    <inertial>
      <origin
        xyz="0 0 0"
        rpy="0 0 0" />
      <mass value="100" />
    <inertia
      ixx="1" ixy="0" ixz="0"
              iyy="1" iyz="0"
                      izz="1" />
    </inertial>
  </xacro:davinci_link>

  <joint name="p4_arm_elevation" type="prismatic">
    <parent link="base_link"/>
    <child link="p4_arm_base"/>
    <origin
      xyz="0 0 0"
      rpy="0 0 0" />
    <axis xyz="0 0 1"/>
    <limit
      lower="0"
      upper="1"
      effort="10000"
      velocity="1" />
  </joint>

</robot>
